<?xml version="1.0" ?>
<!-- =================================================================================== -->
<!-- |    This document was autogenerated by xacro from x6.urdf.xacro                  | -->
<!-- |    EDITING THIS FILE BY HAND IS NOT RECOMMENDED                                 | -->
<!-- =================================================================================== -->
<robot name="x6" xmlns:controller="http://playerstage.sourceforge.net/gazebo/xmlschema/#controller" xmlns:interface="http://playerstage.sourceforge.net/gazebo/xmlschema/#interface" xmlns:sensor="http://playerstage.sourceforge.net/gazebo/xmlschema/#sensor" xmlns:xacro="http://playerstage.sourceforge.net/gazebo/xmlschema/#interface">
  <!-- Included URDF Files -->
  <link name="base">
    <inertial>
      <mass value="10"/>
      <origin rpy="0 0 0" xyz="0.0 0.0 0.0"/>
      <inertia ixx="0.001" ixy="0.0" ixz="0.0" iyy="0.001" iyz="0.0" izz="0.001"/>
    </inertial>
  </link>
  <link name="x6_base_link">
    <visual>
      <geometry>
        <mesh filename="package://x6_description/meshes/x6_common/x6_link_0_gnd.dae"/>
        <!--<cylinder radius="${base_radius}" length="${base_height}"/>-->
      </geometry>
      <origin rpy="0 0 0" xyz="0 0 0.004"/>
      <material name="blue">
        <color rgba="0 0 .8 1"/>
      </material>
    </visual>
    <collision>
      <geometry>
        <!--<cylinder radius="${base_radius}" length="${base_height}"/>-->
        <mesh filename="package://x6_description/meshes/x6_common/x6_link_0_gnd.stl"/>
      </geometry>
      <origin rpy="0 0 0" xyz="0 0 0.004"/>
    </collision>
    <inertial>
      <mass value="0.1"/>
      <origin rpy="0 0 0" xyz="0.0 0.0 0.0"/>
      <inertia ixx="0.001" ixy="0.0" ixz="0.0" iyy="0.001" iyz="0.0" izz="0.001"/>
    </inertial>
  </link>
  <gazebo reference="x6_base_link">
    <selfCollide>true</selfCollide>
    <material>x6_material/Grey</material>
    <!--<material>HLUGV/Green</material>-->
  </gazebo>
  <link name="x6_link1">
    <visual>
      <geometry>
        <mesh filename="package://x6_description/meshes/x6_common/x6_link_1.dae"/>
        <!--                    <box size="${j1_x} ${j1_y} ${j1_z}" />-->
      </geometry>
      <origin rpy="0 0 1.5707963268" xyz="0 0 -0.008"/>
      <material name="green">
        <color rgba="0.9 0.9 0.9 1"/>
      </material>
    </visual>
    <collision>
      <geometry>
        <mesh filename="package://x6_description/meshes/x6_common/x6_link_1.stl"/>
        <!--<box size="${j1_x} ${j1_y} ${j1_z}" />-->
      </geometry>
      <origin rpy="0 0 1.5707963268" xyz="0 0 -0.008"/>
    </collision>
    <inertial>
      <mass value="3"/>
      <origin rpy="0 0 0" xyz="0.0 0.0 0.0"/>
      <inertia ixx="0.001" ixy="0.0" ixz="0.0" iyy="0.001" iyz="0.0" izz="0.001"/>
    </inertial>
  </link>
  <gazebo reference="x6_link1">
    <selfCollide>true</selfCollide>
    <material>x6_material/White</material>
    <!--<material>Gazebo/Blue</material>-->
  </gazebo>
  <link name="x6_link2">
    <visual>
      <geometry>
        <mesh filename="package://x6_description/meshes/x6_common/x6_link_2.dae"/>
        <!--<mesh filename="package://katana_description/meshes/katana/katana_internal_controlbox.stl" />-->
      </geometry>
      <!--<origin xyz="${j2_length/2 - j2_overhang_rear/2 } 0 0" rpy="0 ${pi/2} 0"/>-->
      <origin rpy="0 1.5707963268 3.1415926536" xyz="0 0 0"/>
      <material name="red">
        <color rgba="0.6 0.6 0.6 1"/>
      </material>
    </visual>
    <collision>
      <geometry>
        <mesh filename="package://x6_description/meshes/x6_common/x6_link_2.stl"/>
        <!--<cylinder radius="0.02" length="${j2_length}" />-->
      </geometry>
      <origin rpy="0 1.5707963268 3.1415926536" xyz="0 0 0"/>
    </collision>
    <inertial>
      <mass value="0.5"/>
      <origin rpy="0 0 0" xyz="0.0 0.0 0.0"/>
      <inertia ixx="0.001" ixy="0.0" ixz="0.0" iyy="0.001" iyz="0.0" izz="0.001"/>
    </inertial>
  </link>
  <gazebo reference="x6_link2">
    <selfCollide>true</selfCollide>
    <material>x6_material/Grey</material>
    <!--<material>HLUGV/Green</material>-->
  </gazebo>
  <link name="x6_link3">
    <visual>
      <geometry>
        <mesh filename="package://x6_description/meshes/x6/x6_link_3.dae"/>
        <!--<cylinder radius="0.02" length="${j3_length}" />-->
      </geometry>
      <origin rpy="1.5707963268 0 1.5707963268" xyz="0 0 0"/>
      <material name="red">
                  
                </material>
    </visual>
    <collision>
      <geometry>
        <mesh filename="package://x6_description/meshes/x6/x6_link_3.stl"/>
        <!--  <cylinder radius="0.02" length="${j3_length}" />-->
      </geometry>
      <origin rpy="1.5707963268 0 1.5707963268" xyz="0 0 0"/>
    </collision>
    <inertial>
      <mass value="0.1"/>
      <origin rpy="0 0 0" xyz="0.0 0.0 0.0"/>
      <inertia ixx="0.001" ixy="0.0" ixz="0.0" iyy="0.001" iyz="0.0" izz="0.001"/>
    </inertial>
  </link>
  <gazebo reference="x6_link3">
    <selfCollide>true</selfCollide>
    <material>x6_material/Grey</material>
    <!--<material>HLUGV/Green</material>-->
  </gazebo>
  <link name="x6_link4">
    <visual>
      <geometry>
        <mesh filename="package://x6_description/meshes/x6/x6_link_4.dae"/>
        <!--                    <cylinder radius="0.002" length="0.001" />-->
      </geometry>
      <origin rpy="3.1415926536 0 0" xyz="0 0 -0.1"/>
      <material name="red">
                  
                </material>
    </visual>
    <collision>
      <geometry>
        <mesh filename="package://x6_description/meshes/x6/x6_link_4.stl"/>
        <!--<cylinder radius="0.02" length="${j4_length}" />-->
      </geometry>
      <origin rpy="3.1415926536 0 0" xyz="0 0 -0.1"/>
    </collision>
    <inertial>
      <mass value="0.01"/>
      <origin rpy="0 0 0" xyz="0.0 0.0 0.0"/>
      <inertia ixx="0.001" ixy="0.0" ixz="0.0" iyy="0.001" iyz="0.0" izz="0.001"/>
    </inertial>
  </link>
  <gazebo reference="x6_link5">
    <selfCollide>true</selfCollide>
    <material>x6_material/Grey</material>
    <!--<material>HLUGV/Green</material>-->
  </gazebo>
  <link name="x6_link5">
    <visual>
      <geometry>
        <mesh filename="package://x6_description/meshes/x6_common/x6_link_4_0120.dae"/>
        <!--  <cylinder radius="0.02" length="${j4_length}" />-->
      </geometry>
      <origin rpy="-1.5707963268 0 0" xyz="0 0 0"/>
      <material name="red">
                  
                </material>
    </visual>
    <collision>
      <geometry>
        <mesh filename="package://x6_description/meshes/x6_common/x6_link_4_0120.stl"/>
        <!--<cylinder radius="0.02" length="${j4_length}" />-->
      </geometry>
      <origin rpy="-1.5707963268 0 0" xyz="0 0 0"/>
    </collision>
    <inertial>
      <mass value="0.01"/>
      <origin rpy="0 0 0" xyz="0.0 0.0 0.0"/>
      <inertia ixx="0.001" ixy="0.0" ixz="0.0" iyy="0.001" iyz="0.0" izz="0.001"/>
    </inertial>
  </link>
  <gazebo reference="x6_link5">
    <selfCollide>true</selfCollide>
    <material>x6_material/Grey</material>
    <!--<material>HLUGV/Green</material>-->
  </gazebo>
  <link name="x6_link6">
    <visual>
      <geometry>
        <mesh filename="package://x6_description/meshes/x6/x6_link_6.dae"/>
        <!--<cylinder radius="0.002" length="0.001" />-->
      </geometry>
      <origin rpy="0 0 0" xyz="0 0 -0.036"/>
      <material name="red">
                  
                </material>
    </visual>
    <collision>
      <geometry>
        <mesh filename="package://x6_description/meshes/x6/x6_link_6.stl"/>
        <!--<cylinder radius="0.002" length="0.001" />-->
      </geometry>
      <origin rpy="0 0 0" xyz="0 0 -0.036"/>
    </collision>
    <inertial>
      <mass value="0.01"/>
      <origin rpy="0 0 0" xyz="0.0 0.0 0.0"/>
      <inertia ixx="0.001" ixy="0.0" ixz="0.0" iyy="0.001" iyz="0.0" izz="0.001"/>
    </inertial>
  </link>
  <gazebo reference="x6_link6">
    <selfCollide>true</selfCollide>
    <material>x6_material/Grey</material>
    <!--<material>HLUGV/Green</material>-->
  </gazebo>
  <link name="x6_toolframe">
    <visual>
      <geometry>
        <mesh filename="package://x6_description/meshes/x6_common/x6_rot_racket.dae"/>
      </geometry>
      <origin rpy="0 -1.5707963268 3.1415926536" xyz="-0.0015 0 0.01"/>
      <material name="blue">
        <color rgba="0 0 .8 1"/>
      </material>
    </visual>
    <collision>
      <geometry>
        <!-- <box size="0.009 0.025 0.003"/> -->
        <mesh filename="package://x6_description/meshes/x6_common/x6_rot_racket.stl"/>
      </geometry>
      <origin rpy="0 -1.5707963268 3.1415926536" xyz="-0.0015 0 0.01"/>
    </collision>
    <inertial>
      <mass value="0.05"/>
      <origin rpy="0 0 0" xyz="0.0 0.0 0.0"/>
      <inertia ixx="0.001" ixy="0.0" ixz="0.0" iyy="0.001" iyz="0.0" izz="0.001"/>
    </inertial>
  </link>
  <gazebo reference="x6_toolframe">
    <selfCollide>true</selfCollide>
    <material>x6_material/Grey</material>
    <!--<material>HLUGV/Green</material>-->
  </gazebo>
  <joint name="x6_base_joint" type="fixed">
    <origin rpy="0 0 0" xyz="0 0 0"/>
    <parent link="base"/>
    <child link="x6_base_link"/>
  </joint>
  <joint name="joint1" type="revolute">
    <parent link="x6_base_link"/>
    <child link="x6_link1"/>
    <axis xyz="0 0 1"/>
    <origin xyz="0 0 0.008"/>
    <limit effort="50.0" lower="-2.53" upper="2.53" velocity="2.617"/>
    <!-- TODO: give correct effort limits -->
    <dynamics damping="1.0" friction="1.0"/>
  </joint>
  <joint name="joint2" type="revolute">
    <parent link="x6_link1"/>
    <child link="x6_link2"/>
    <axis xyz="0 0 1"/>
    <origin rpy="1.5707963268 0 0" xyz="0 0 0.276"/>
    <limit effort="50.0" lower="-2.181" upper="2.0071" velocity="2.617"/>
    <dynamics damping="1.0" friction="1.0"/>
  </joint>
  <joint name="joint3" type="revolute">
    <parent link="x6_link2"/>
    <child link="x6_link3"/>
    <axis xyz="0 0 1 "/>
    <origin rpy="0 0 1.5707963268" xyz="0 0.307 0"/>
    <limit effort="30.0" lower="-2.007" upper="2.007" velocity="2.617"/>
    <dynamics damping="1.0" friction="1.0"/>
  </joint>
  <joint name="joint4" type="revolute">
    <parent link="x6_link3"/>
    <child link="x6_link4"/>
    <axis xyz="0 0 1"/>
    <origin rpy="1.5707963268 0 -1.5707963268" xyz="0 0 0.0"/>
    <limit effort="30.0" lower="-1.83" upper="1.83" velocity="2.617"/>
    <!-- TODO: give correct effort limits -->
    <dynamics damping="1.0" friction="1.0"/>
  </joint>
  <joint name="joint5" type="revolute">
    <parent link="x6_link4"/>
    <child link="x6_link5"/>
    <axis xyz="0 0 1"/>
    <!-- <origin xyz="0 0 ${-j3_length - j4_length}" rpy="${-pi/2} 0 0"/> -->
    <origin rpy="-1.5707963268 1.5707963268 0" xyz="0 0 -0.311"/>
    <limit effort="30.0" lower="-1.57" upper="1.57" velocity="2.617"/>
    <!-- <limit effort="0.1" lower="0.01" upper="0.01" velocity="0.1"/> -->
    <dynamics damping="1.0" friction="1.0"/>
  </joint>
  <joint name="joint6" type="revolute">
    <parent link="x6_link5"/>
    <child link="x6_link6"/>
    <axis xyz="0 0 1"/>
    <origin rpy="-1.5707963268 0 0" xyz="0 0.126 0.018"/>
    <limit effort="10.0" lower="-1.57" upper="1.57" velocity="2.617"/>
    <!-- TODO: give correct effort limits -->
    <dynamics damping="1.0" friction="1.0"/>
  </joint>
  <joint name="tool_frame" type="fixed">
    <parent link="x6_link6"/>
    <child link="x6_toolframe"/>
    <axis xyz="0 0 1"/>
    <!-- <origin xyz="0 ${j6_length} 0" rpy="0 0 ${pi/2}"/> -->
    <origin rpy="0 -1.5707963268 4.7123889804" xyz="0 0.012 0.11"/>
  </joint>
  <transmission name="joint1_trans" type="pr2_mechanism_model/SimpleTransmission">
    <actuator name="joint1_motor"/>
    <joint name="joint1"/>
    <mechanicalReduction>1.0</mechanicalReduction>
  </transmission>
  <transmission name="joint2_trans" type="pr2_mechanism_model/SimpleTransmission">
    <actuator name="joint2_motor"/>
    <joint name="joint2"/>
    <mechanicalReduction>1.0</mechanicalReduction>
  </transmission>
  <transmission name="joint3_trans" type="pr2_mechanism_model/SimpleTransmission">
    <actuator name="joint3_motor"/>
    <joint name="joint3"/>
    <mechanicalReduction>1.0</mechanicalReduction>
  </transmission>
  <transmission name="joint4_trans" type="pr2_mechanism_model/SimpleTransmission">
    <actuator name="joint4_motor"/>
    <joint name="joint4"/>
    <mechanicalReduction>1.0</mechanicalReduction>
  </transmission>
  <transmission name="joint6_trans" type="pr2_mechanism_model/SimpleTransmission">
    <actuator name="joint6_motor"/>
    <joint name="joint6"/>
    <mechanicalReduction>1.0</mechanicalReduction>
  </transmission>
</robot>
