<?xml version="1.0" ?>
<!-- =================================================================================== -->
<!-- |    This document was autogenerated by xacro from x6.urdf.xacro                  | -->
<!-- |    EDITING THIS FILE BY HAND IS NOT RECOMMENDED                                 | -->
<!-- =================================================================================== -->
<robot name="x6" xmlns:xacro="http://www.ros.org/wiki/xacro">
  <!-- Included URDF Files -->
  <link name="base">
    <inertial>
      <mass value="10"/>
      <origin rpy="0 0 0" xyz="0.0 0.0 0.0"/>
      <inertia ixx="0.001" ixy="0.0" ixz="0.0" iyy="0.001" iyz="0.0" izz="0.001"/>
    </inertial>
  </link>
  <!-- Used for fixing robot to Gazebo 'base_link' -->
  <link name="world"/>
  <joint name="fixed" type="fixed">
    <parent link="world"/>
    <child link="base"/>
  </joint>
  <link name="x6_base_link">
    <visual>
      <geometry>
        <!-- <mesh filename="package://x6_description/meshes/x6_common/x6_link_0_gnd.dae"/> -->
        <cylinder length="0.008" radius="0.05"/>
      </geometry>
      <origin rpy="0 0 0" xyz="0 0 0.004"/>
      <material name="blue">
        <color rgba="0 0 .8 1"/>
      </material>
    </visual>
    <collision>
      <geometry>
        <cylinder length="0.008" radius="0.05"/>
        <!-- <mesh filename="package://x6_description/meshes/x6_common/x6_link_0_gnd.stl"/> -->
      </geometry>
      <origin rpy="0 0 0" xyz="0 0 0.004"/>
    </collision>
    <inertial>
      <mass value="0.1"/>
      <origin rpy="0 0 0" xyz="0.0 0.0 0.0"/>
      <inertia ixx="0.001" ixy="0.0" ixz="0.0" iyy="0.001" iyz="0.0" izz="0.001"/>
    </inertial>
  </link>
  <gazebo reference="x6_base_link">
    <selfCollide>true</selfCollide>
    <material>x6_material/Grey</material>
    <!--<material>HLUGV/Green</material>-->
  </gazebo>
  <link name="x6_link1">
    <visual>
      <geometry>
        <mesh filename="package://x6_description/meshes/x6_common/x6_link_1.dae"/>
        <!--                    <box size="${j1_x} ${j1_y} ${j1_z}" />-->
      </geometry>
      <origin rpy="0 0 1.5707963268" xyz="0 0 -0.008"/>
      <material name="green">
        <color rgba="0.9 0.9 0.9 1"/>
      </material>
    </visual>
    <collision>
      <geometry>
        <mesh filename="package://x6_description/meshes/x6_common/x6_link_1.stl"/>
        <!--<box size="${j1_x} ${j1_y} ${j1_z}" />-->
      </geometry>
      <origin rpy="0 0 1.5707963268" xyz="0 0 -0.008"/>
    </collision>
    <inertial>
      <mass value="3"/>
      <origin rpy="0 0 0" xyz="0.0 0.0 0.0"/>
      <inertia ixx="0.001" ixy="0.0" ixz="0.0" iyy="0.001" iyz="0.0" izz="0.001"/>
    </inertial>
  </link>
  <gazebo reference="x6_link1">
    <selfCollide>true</selfCollide>
    <material>x6_material/White</material>
    <!--<material>Gazebo/Blue</material>-->
  </gazebo>
  <link name="x6_link2">
    <visual>
      <geometry>
        <mesh filename="package://x6_description/meshes/x6_common/x6_link_2.dae"/>
        <!--<mesh filename="package://katana_description/meshes/katana/katana_internal_controlbox.stl" />-->
      </geometry>
      <!--<origin xyz="${j2_length/2 - j2_overhang_rear/2 } 0 0" rpy="0 ${pi/2} 0"/>-->
      <origin rpy="0 1.5707963268 3.1415926536" xyz="0 0 0"/>
      <material name="red">
        <color rgba="0.6 0.6 0.6 1"/>
      </material>
    </visual>
    <collision>
      <geometry>
        <mesh filename="package://x6_description/meshes/x6_common/x6_link_2.stl"/>
        <!--<cylinder radius="0.02" length="${j2_length}" />-->
      </geometry>
      <origin rpy="0 1.5707963268 3.1415926536" xyz="0 0 0"/>
    </collision>
    <inertial>
      <mass value="0.5"/>
      <origin rpy="0 0 0" xyz="0.0 0.0 0.0"/>
      <inertia ixx="0.001" ixy="0.0" ixz="0.0" iyy="0.001" iyz="0.0" izz="0.001"/>
    </inertial>
  </link>
  <gazebo reference="x6_link2">
    <selfCollide>true</selfCollide>
    <material>x6_material/Grey</material>
    <!--<material>HLUGV/Green</material>-->
  </gazebo>
  <link name="x6_link3">
    <visual>
      <geometry>
        <mesh filename="package://x6_description/meshes/x6/x6_link_3.dae"/>
        <!--<cylinder radius="0.02" length="${j3_length}" />-->
      </geometry>
      <origin rpy="1.5707963268 0 1.5707963268" xyz="0 0 0"/>
      <material name="red">

                </material>
    </visual>
    <collision>
      <geometry>
        <mesh filename="package://x6_description/meshes/x6/x6_link_3.stl"/>
        <!--  <cylinder radius="0.02" length="${j3_length}" />-->
      </geometry>
      <origin rpy="1.5707963268 0 1.5707963268" xyz="0 0 0"/>
    </collision>
    <inertial>
      <mass value="0.1"/>
      <origin rpy="0 0 0" xyz="0.0 0.0 0.0"/>
      <inertia ixx="0.001" ixy="0.0" ixz="0.0" iyy="0.001" iyz="0.0" izz="0.001"/>
    </inertial>
  </link>
  <gazebo reference="x6_link3">
    <selfCollide>true</selfCollide>
    <material>x6_material/Grey</material>
    <!--<material>HLUGV/Green</material>-->
  </gazebo>
  <link name="x6_link4">
    <visual>
      <geometry>
        <mesh filename="package://x6_description/meshes/x6/x6_link_4.dae"/>
        <!--                    <cylinder radius="0.002" length="0.001" />-->
      </geometry>
      <origin rpy="3.1415926536 0 0" xyz="0 0 -0.1"/>
      <material name="red">

                </material>
    </visual>
    <collision>
      <geometry>
        <mesh filename="package://x6_description/meshes/x6/x6_link_4.stl"/>
        <!--<cylinder radius="0.02" length="${j4_length}" />-->
      </geometry>
      <origin rpy="3.1415926536 0 0" xyz="0 0 -0.1"/>
    </collision>
    <inertial>
      <mass value="0.01"/>
      <origin rpy="0 0 0" xyz="0.0 0.0 0.0"/>
      <inertia ixx="0.001" ixy="0.0" ixz="0.0" iyy="0.001" iyz="0.0" izz="0.001"/>
    </inertial>
  </link>
  <gazebo reference="x6_link5">
    <selfCollide>true</selfCollide>
    <material>x6_material/Grey</material>
    <!--<material>HLUGV/Green</material>-->
  </gazebo>
  <link name="x6_link5">
    <visual>
      <geometry>
        <mesh filename="package://x6_description/meshes/x6_common/x6_link_4_0120.dae"/>
        <!--  <cylinder radius="0.02" length="${j4_length}" />-->
      </geometry>
      <origin rpy="-1.5707963268 0 0" xyz="0 0 0"/>
      <material name="red">

                </material>
    </visual>
    <collision>
      <geometry>
        <mesh filename="package://x6_description/meshes/x6_common/x6_link_4_0120.stl"/>
        <!--<cylinder radius="0.02" length="${j4_length}" />-->
      </geometry>
      <origin rpy="-1.5707963268 0 0" xyz="0 0 0"/>
    </collision>
    <inertial>
      <mass value="0.01"/>
      <origin rpy="0 0 0" xyz="0.0 0.0 0.0"/>
      <inertia ixx="0.001" ixy="0.0" ixz="0.0" iyy="0.001" iyz="0.0" izz="0.001"/>
    </inertial>
  </link>
  <gazebo reference="x6_link5">
    <selfCollide>true</selfCollide>
    <material>x6_material/Grey</material>
    <!--<material>HLUGV/Green</material>-->
  </gazebo>
  <link name="x6_link6">
    <visual>
      <geometry>
        <mesh filename="package://x6_description/meshes/x6/x6_link_6.dae"/>
        <!--<cylinder radius="0.002" length="0.001" />-->
      </geometry>
      <origin rpy="0 0 0" xyz="0 0 -0.036"/>
      <material name="red">

      </material>
    </visual>
    <collision>
      <geometry>
        <mesh filename="package://x6_description/meshes/x6/x6_link_6.stl"/>
        <!--<cylinder radius="0.002" length="0.001" />-->
      </geometry>
      <origin rpy="0 0 0" xyz="0 0 -0.036"/>
    </collision>
    <inertial>
      <mass value="0.01"/>
      <origin rpy="0 0 0" xyz="0.0 0.0 0.0"/>
      <inertia ixx="0.001" ixy="0.0" ixz="0.0" iyy="0.001" iyz="0.0" izz="0.001"/>
    </inertial>
  </link>
  <gazebo reference="x6_link6">
    <selfCollide>true</selfCollide>
    <material>x6_material/Grey</material>
    <!--<material>HLUGV/Green</material>-->
  </gazebo>
  <link name="x6_toolframe">
    <visual>
      <geometry>
        <mesh filename="package://x6_description/meshes/x6_common/x6_rot_racket.dae"/>
        <!-- <cylinder radius="0.08" length="0.01" /> -->
      </geometry>
      <origin rpy="0 -1.5707963268 3.1415926536" xyz="-0.0015 0 0.01"/>
      <!-- <origin xyz="-0.0215 0 0.01" rpy="0 0 0"/> -->
      <material name="blue">
        <color rgba="0 0 .8 1"/>
      </material>
    </visual>
    <collision>
      <geometry>
        <!-- <mesh filename="package://x6_description/meshes/x6_common/x6_rot_racket.stl"/> -->
        <cylinder length="0.01" radius="0.08"/>
      </geometry>
      <!--<origin xyz="-0.0015 0 0.01" rpy="0 -${pi/2} ${pi}"/> -->
      <origin rpy="0 0 0" xyz="-0.0215 0 0.01"/>
      <surface>
        <contact>
          <ode>
            <kp>1e+08</kp>
            <kd>10000</kd>
          </ode>
        </contact>
        <friction>
          <ode>
            <mu>0</mu>
            <mu2>0</mu2>
          </ode>
        </friction>
      </surface>
    </collision>
    <inertial>
      <mass value="0.01"/>
      <origin rpy="0 0 0" xyz="0.0 0.0 0.0"/>
      <inertia ixx="0.001" ixy="0.0" ixz="0.0" iyy="0.001" iyz="0.0" izz="0.001"/>
    </inertial>
  </link>
  <gazebo reference="x6_toolframe">
    <selfCollide>true</selfCollide>
    <material>Gazebo/Grey</material>
  </gazebo>
  <joint name="x6_base_joint" type="fixed">
    <origin rpy="0 0 0" xyz="0 0 0"/>
    <parent link="base"/>
    <child link="x6_base_link"/>
  </joint>
  <joint name="joint1" type="revolute">
    <parent link="x6_base_link"/>
    <child link="x6_link1"/>
    <axis xyz="0 0 1"/>
    <origin xyz="0 0 0.008"/>
    <limit effort="50.0" lower="-2.53" upper="2.53" velocity="2.617"/>
    <!-- TODO: give correct effort limits -->
    <dynamics damping="1.0" friction="1.0"/>
  </joint>
  <joint name="joint2" type="revolute">
    <parent link="x6_link1"/>
    <child link="x6_link2"/>
    <axis xyz="0 0 1"/>
    <origin rpy="1.5707963268 0 0" xyz="0 0 0.276"/>
    <limit effort="50.0" lower="-2.181" upper="2.0071" velocity="2.617"/>
    <dynamics damping="1.0" friction="1.0"/>
  </joint>
  <joint name="joint3" type="revolute">
    <parent link="x6_link2"/>
    <child link="x6_link3"/>
    <axis xyz="0 0 1 "/>
    <origin rpy="0 0 1.5707963268" xyz="0 0.307 0"/>
    <limit effort="30.0" lower="-2.007" upper="2.007" velocity="2.617"/>
    <dynamics damping="1.0" friction="1.0"/>
  </joint>
  <joint name="joint4" type="revolute">
    <parent link="x6_link3"/>
    <child link="x6_link4"/>
    <axis xyz="0 0 1"/>
    <origin rpy="1.5707963268 0 -1.5707963268" xyz="0 0 0.0"/>
    <limit effort="30.0" lower="-1.83" upper="1.83" velocity="2.617"/>
    <!-- TODO: give correct effort limits -->
    <dynamics damping="1.0" friction="1.0"/>
  </joint>
  <joint name="joint5" type="revolute">
    <!--<joint name="joint5" type="fixed">-->
    <parent link="x6_link4"/>
    <child link="x6_link5"/>
    <axis xyz="0 0 1"/>
    <origin rpy="-1.5707963268 0 0" xyz="0 0 -0.311"/>
    <!--<origin xyz="0 0 ${-j3_length - j4_length}" rpy="${-pi/2} ${pi/2} 0"/>-->
    <limit effort="30.0" lower="-1.57" upper="1.57" velocity="2.617"/>
    <!-- <limit effort="0.1" lower="0.01" upper="0.01" velocity="0.1"/> -->
    <!--<dynamics damping="1.0" friction="1.0"/>-->
  </joint>
  <joint name="joint6" type="revolute">
    <parent link="x6_link5"/>
    <child link="x6_link6"/>
    <axis xyz="0 0 1"/>
    <origin rpy="-1.5707963268 0 0" xyz="0 0.126 0.018"/>
    <limit effort="10.0" lower="-1.57" upper="1.57" velocity="2.617"/>
    <!-- TODO: give correct effort limits -->
    <dynamics damping="1.0" friction="1.0"/>
  </joint>
  <joint name="tool_frame" type="fixed">
    <parent link="x6_link6"/>
    <child link="x6_toolframe"/>
    <axis xyz="0 0 1"/>
    <!-- <origin xyz="0 ${j6_length} 0" rpy="0 0 ${pi/2}"/> -->
    <origin rpy="3.1415926536 -1.5707963268 4.7123889804" xyz="0 0.012 0.11"/>
  </joint>
  <transmission name="joint1_trans">
    <type>transmission_interface/SimpleTransmission</type>
    <joint name="joint1">
      <hardwareInterface>EffortJointInterface</hardwareInterface>
    </joint>
    <actuator name="joint1_motor">
      <hardwareInterface>EffortJointInterface</hardwareInterface>
      <mechanicalReduction>1</mechanicalReduction>
    </actuator>
  </transmission>
  <transmission name="joint2_trans">
    <type>transmission_interface/SimpleTransmission</type>
    <joint name="joint2">
      <hardwareInterface>EffortJointInterface</hardwareInterface>
    </joint>
    <actuator name="joint2_motor">
      <hardwareInterface>EffortJointInterface</hardwareInterface>
      <mechanicalReduction>1</mechanicalReduction>
    </actuator>
  </transmission>
  <transmission name="joint3_trans">
    <type>transmission_interface/SimpleTransmission</type>
    <joint name="joint3">
      <hardwareInterface>EffortJointInterface</hardwareInterface>
    </joint>
    <actuator name="joint3_motor">
      <hardwareInterface>EffortJointInterface</hardwareInterface>
      <mechanicalReduction>1</mechanicalReduction>
    </actuator>
  </transmission>
  <transmission name="joint4_trans">
    <type>transmission_interface/SimpleTransmission</type>
    <joint name="joint4">
      <hardwareInterface>EffortJointInterface</hardwareInterface>
    </joint>
    <actuator name="joint4_motor">
      <hardwareInterface>EffortJointInterface</hardwareInterface>
      <mechanicalReduction>1</mechanicalReduction>
    </actuator>
  </transmission>
  <transmission name="joint5_trans">
    <type>transmission_interface/SimpleTransmission</type>
    <joint name="joint5">
      <hardwareInterface>EffortJointInterface</hardwareInterface>
    </joint>
    <actuator name="joint5_motor">
      <hardwareInterface>EffortJointInterface</hardwareInterface>
      <mechanicalReduction>1</mechanicalReduction>
    </actuator>
  </transmission>
  <transmission name="joint6_trans">
    <type>transmission_interface/SimpleTransmission</type>
    <joint name="joint6">
      <hardwareInterface>EffortJointInterface</hardwareInterface>
    </joint>
    <actuator name="joint6_motor">
      <hardwareInterface>EffortJointInterface</hardwareInterface>
      <mechanicalReduction>1</mechanicalReduction>
    </actuator>
  </transmission>
  <gazebo>
    <plugin filename="libgazebo_ros_control.so" name="gazebo_ros_control">
      <robotNamespace>/x6</robotNamespace>
    </plugin>
  </gazebo>
</robot>

